[Wed Jan 23 13:45:18.439037 2019] [wsgi:error] [pid 9746:tid 140438229399296] [remote 14.143.35.158:40948] [2019-01-23 13:45:18,437] ERROR in app: Exception on /feed [GET]
[Wed Jan 23 13:45:18.439083 2019] [wsgi:error] [pid 9746:tid 140438229399296] [remote 14.143.35.158:40948] Traceback (most recent call last):
[Wed Jan 23 13:45:18.439087 2019] [wsgi:error] [pid 9746:tid 140438229399296] [remote 14.143.35.158:40948]   File "/home/ubuntu/.local/lib/python3.6/site-packages/flask/app.py", line 2292, in wsgi_app
[Wed Jan 23 13:45:18.439093 2019] [wsgi:error] [pid 9746:tid 140438229399296] [remote 14.143.35.158:40948]     response = self.full_dispatch_request()
[Wed Jan 23 13:45:18.439096 2019] [wsgi:error] [pid 9746:tid 140438229399296] [remote 14.143.35.158:40948]   File "/home/ubuntu/.local/lib/python3.6/site-packages/flask/app.py", line 1815, in full_dispatch_request
[Wed Jan 23 13:45:18.439099 2019] [wsgi:error] [pid 9746:tid 140438229399296] [remote 14.143.35.158:40948]     rv = self.handle_user_exception(e)
[Wed Jan 23 13:45:18.439102 2019] [wsgi:error] [pid 9746:tid 140438229399296] [remote 14.143.35.158:40948]   File "/home/ubuntu/.local/lib/python3.6/site-packages/flask/app.py", line 1718, in handle_user_exception
[Wed Jan 23 13:45:18.439105 2019] [wsgi:error] [pid 9746:tid 140438229399296] [remote 14.143.35.158:40948]     reraise(exc_type, exc_value, tb)
[Wed Jan 23 13:45:18.439108 2019] [wsgi:error] [pid 9746:tid 140438229399296] [remote 14.143.35.158:40948]   File "/home/ubuntu/.local/lib/python3.6/site-packages/flask/_compat.py", line 35, in reraise
[Wed Jan 23 13:45:18.439111 2019] [wsgi:error] [pid 9746:tid 140438229399296] [remote 14.143.35.158:40948]     raise value
[Wed Jan 23 13:45:18.439114 2019] [wsgi:error] [pid 9746:tid 140438229399296] [remote 14.143.35.158:40948]   File "/home/ubuntu/.local/lib/python3.6/site-packages/flask/app.py", line 1813, in full_dispatch_request
[Wed Jan 23 13:45:18.439117 2019] [wsgi:error] [pid 9746:tid 140438229399296] [remote 14.143.35.158:40948]     rv = self.dispatch_request()
[Wed Jan 23 13:45:18.439119 2019] [wsgi:error] [pid 9746:tid 140438229399296] [remote 14.143.35.158:40948]   File "/home/ubuntu/.local/lib/python3.6/site-packages/flask/app.py", line 1799, in dispatch_request
[Wed Jan 23 13:45:18.439122 2019] [wsgi:error] [pid 9746:tid 140438229399296] [remote 14.143.35.158:40948]     return self.view_functions[rule.endpoint](**req.view_args)
[Wed Jan 23 13:45:18.439125 2019] [wsgi:error] [pid 9746:tid 140438229399296] [remote 14.143.35.158:40948]   File "/home/ubuntu/flask/cc.py", line 87, in display_grid
[Wed Jan 23 13:45:18.439128 2019] [wsgi:error] [pid 9746:tid 140438229399296] [remote 14.143.35.158:40948]     df=pd.read_csv('database.csv')
[Wed Jan 23 13:45:18.439131 2019] [wsgi:error] [pid 9746:tid 140438229399296] [remote 14.143.35.158:40948]   File "/home/ubuntu/.local/lib/python3.6/site-packages/pandas/io/parsers.py", line 678, in parser_f
[Wed Jan 23 13:45:18.439134 2019] [wsgi:error] [pid 9746:tid 140438229399296] [remote 14.143.35.158:40948]     return _read(filepath_or_buffer, kwds)
[Wed Jan 23 13:45:18.439137 2019] [wsgi:error] [pid 9746:tid 140438229399296] [remote 14.143.35.158:40948]   File "/home/ubuntu/.local/lib/python3.6/site-packages/pandas/io/parsers.py", line 440, in _read
[Wed Jan 23 13:45:18.439140 2019] [wsgi:error] [pid 9746:tid 140438229399296] [remote 14.143.35.158:40948]     parser = TextFileReader(filepath_or_buffer, **kwds)
[Wed Jan 23 13:45:18.439143 2019] [wsgi:error] [pid 9746:tid 140438229399296] [remote 14.143.35.158:40948]   File "/home/ubuntu/.local/lib/python3.6/site-packages/pandas/io/parsers.py", line 787, in __init__
[Wed Jan 23 13:45:18.439146 2019] [wsgi:error] [pid 9746:tid 140438229399296] [remote 14.143.35.158:40948]     self._make_engine(self.engine)
[Wed Jan 23 13:45:18.439148 2019] [wsgi:error] [pid 9746:tid 140438229399296] [remote 14.143.35.158:40948]   File "/home/ubuntu/.local/lib/python3.6/site-packages/pandas/io/parsers.py", line 1014, in _make_engine
[Wed Jan 23 13:45:18.439151 2019] [wsgi:error] [pid 9746:tid 140438229399296] [remote 14.143.35.158:40948]     self._engine = CParserWrapper(self.f, **self.options)
[Wed Jan 23 13:45:18.439159 2019] [wsgi:error] [pid 9746:tid 140438229399296] [remote 14.143.35.158:40948]   File "/home/ubuntu/.local/lib/python3.6/site-packages/pandas/io/parsers.py", line 1708, in __init__
[Wed Jan 23 13:45:18.439162 2019] [wsgi:error] [pid 9746:tid 140438229399296] [remote 14.143.35.158:40948]     self._reader = parsers.TextReader(src, **kwds)
[Wed Jan 23 13:45:18.439165 2019] [wsgi:error] [pid 9746:tid 140438229399296] [remote 14.143.35.158:40948]   File "pandas/_libs/parsers.pyx", line 384, in pandas._libs.parsers.TextReader.__cinit__
[Wed Jan 23 13:45:18.439168 2019] [wsgi:error] [pid 9746:tid 140438229399296] [remote 14.143.35.158:40948]   File "pandas/_libs/parsers.pyx", line 695, in pandas._libs.parsers.TextReader._setup_parser_source
[Wed Jan 23 13:45:18.439172 2019] [wsgi:error] [pid 9746:tid 140438229399296] [remote 14.143.35.158:40948] FileNotFoundError: File b'database.csv' does not exist
[Wed Jan 23 13:45:18.439194 2019] [wsgi:error] [pid 9746:tid 140438229399296] [remote 14.143.35.158:40948] 
[Wed Jan 23 13:46:03.974080 2019] [wsgi:error] [pid 9746:tid 140438195828480] [remote 14.143.35.158:44391] [2019-01-23 13:46:03,973] ERROR in app: Exception on /feed [GET]
[Wed Jan 23 13:46:03.974108 2019] [wsgi:error] [pid 9746:tid 140438195828480] [remote 14.143.35.158:44391] Traceback (most recent call last):
[Wed Jan 23 13:46:03.974112 2019] [wsgi:error] [pid 9746:tid 140438195828480] [remote 14.143.35.158:44391]   File "/home/ubuntu/.local/lib/python3.6/site-packages/flask/app.py", line 2292, in wsgi_app
[Wed Jan 23 13:46:03.974116 2019] [wsgi:error] [pid 9746:tid 140438195828480] [remote 14.143.35.158:44391]     response = self.full_dispatch_request()
[Wed Jan 23 13:46:03.974120 2019] [wsgi:error] [pid 9746:tid 140438195828480] [remote 14.143.35.158:44391]   File "/home/ubuntu/.local/lib/python3.6/site-packages/flask/app.py", line 1815, in full_dispatch_request
[Wed Jan 23 13:46:03.974124 2019] [wsgi:error] [pid 9746:tid 140438195828480] [remote 14.143.35.158:44391]     rv = self.handle_user_exception(e)
[Wed Jan 23 13:46:03.974127 2019] [wsgi:error] [pid 9746:tid 140438195828480] [remote 14.143.35.158:44391]   File "/home/ubuntu/.local/lib/python3.6/site-packages/flask/app.py", line 1718, in handle_user_exception
[Wed Jan 23 13:46:03.974130 2019] [wsgi:error] [pid 9746:tid 140438195828480] [remote 14.143.35.158:44391]     reraise(exc_type, exc_value, tb)
[Wed Jan 23 13:46:03.974134 2019] [wsgi:error] [pid 9746:tid 140438195828480] [remote 14.143.35.158:44391]   File "/home/ubuntu/.local/lib/python3.6/site-packages/flask/_compat.py", line 35, in reraise
[Wed Jan 23 13:46:03.974137 2019] [wsgi:error] [pid 9746:tid 140438195828480] [remote 14.143.35.158:44391]     raise value
[Wed Jan 23 13:46:03.974140 2019] [wsgi:error] [pid 9746:tid 140438195828480] [remote 14.143.35.158:44391]   File "/home/ubuntu/.local/lib/python3.6/site-packages/flask/app.py", line 1813, in full_dispatch_request
[Wed Jan 23 13:46:03.974144 2019] [wsgi:error] [pid 9746:tid 140438195828480] [remote 14.143.35.158:44391]     rv = self.dispatch_request()
[Wed Jan 23 13:46:03.974147 2019] [wsgi:error] [pid 9746:tid 140438195828480] [remote 14.143.35.158:44391]   File "/home/ubuntu/.local/lib/python3.6/site-packages/flask/app.py", line 1799, in dispatch_request
[Wed Jan 23 13:46:03.974150 2019] [wsgi:error] [pid 9746:tid 140438195828480] [remote 14.143.35.158:44391]     return self.view_functions[rule.endpoint](**req.view_args)
[Wed Jan 23 13:46:03.974154 2019] [wsgi:error] [pid 9746:tid 140438195828480] [remote 14.143.35.158:44391]   File "/home/ubuntu/flask/cc.py", line 87, in display_grid
[Wed Jan 23 13:46:03.974157 2019] [wsgi:error] [pid 9746:tid 140438195828480] [remote 14.143.35.158:44391]     df=pd.read_csv('database.csv')
[Wed Jan 23 13:46:03.974160 2019] [wsgi:error] [pid 9746:tid 140438195828480] [remote 14.143.35.158:44391]   File "/home/ubuntu/.local/lib/python3.6/site-packages/pandas/io/parsers.py", line 678, in parser_f
[Wed Jan 23 13:46:03.974172 2019] [wsgi:error] [pid 9746:tid 140438195828480] [remote 14.143.35.158:44391]     return _read(filepath_or_buffer, kwds)
[Wed Jan 23 13:46:03.974175 2019] [wsgi:error] [pid 9746:tid 140438195828480] [remote 14.143.35.158:44391]   File "/home/ubuntu/.local/lib/python3.6/site-packages/pandas/io/parsers.py", line 440, in _read
[Wed Jan 23 13:46:03.974178 2019] [wsgi:error] [pid 9746:tid 140438195828480] [remote 14.143.35.158:44391]     parser = TextFileReader(filepath_or_buffer, **kwds)
[Wed Jan 23 13:46:03.974180 2019] [wsgi:error] [pid 9746:tid 140438195828480] [remote 14.143.35.158:44391]   File "/home/ubuntu/.local/lib/python3.6/site-packages/pandas/io/parsers.py", line 787, in __init__
[Wed Jan 23 13:46:03.974183 2019] [wsgi:error] [pid 9746:tid 140438195828480] [remote 14.143.35.158:44391]     self._make_engine(self.engine)
[Wed Jan 23 13:46:03.974186 2019] [wsgi:error] [pid 9746:tid 140438195828480] [remote 14.143.35.158:44391]   File "/home/ubuntu/.local/lib/python3.6/site-packages/pandas/io/parsers.py", line 1014, in _make_engine
[Wed Jan 23 13:46:03.974189 2019] [wsgi:error] [pid 9746:tid 140438195828480] [remote 14.143.35.158:44391]     self._engine = CParserWrapper(self.f, **self.options)
[Wed Jan 23 13:46:03.974192 2019] [wsgi:error] [pid 9746:tid 140438195828480] [remote 14.143.35.158:44391]   File "/home/ubuntu/.local/lib/python3.6/site-packages/pandas/io/parsers.py", line 1708, in __init__
[Wed Jan 23 13:46:03.974195 2019] [wsgi:error] [pid 9746:tid 140438195828480] [remote 14.143.35.158:44391]     self._reader = parsers.TextReader(src, **kwds)
[Wed Jan 23 13:46:03.974198 2019] [wsgi:error] [pid 9746:tid 140438195828480] [remote 14.143.35.158:44391]   File "pandas/_libs/parsers.pyx", line 384, in pandas._libs.parsers.TextReader.__cinit__
[Wed Jan 23 13:46:03.974201 2019] [wsgi:error] [pid 9746:tid 140438195828480] [remote 14.143.35.158:44391]   File "pandas/_libs/parsers.pyx", line 695, in pandas._libs.parsers.TextReader._setup_parser_source
[Wed Jan 23 13:46:03.974205 2019] [wsgi:error] [pid 9746:tid 140438195828480] [remote 14.143.35.158:44391] FileNotFoundError: File b'database.csv' does not exist
[Wed Jan 23 13:46:03.974225 2019] [wsgi:error] [pid 9746:tid 140438195828480] [remote 14.143.35.158:44391] 
[Wed Jan 23 13:47:33.038330 2019] [wsgi:error] [pid 9864:tid 139977581049600] [remote 14.143.35.158:51332] [2019-01-23 13:47:33,036] ERROR in app: Exception on /feed [GET]
[Wed Jan 23 13:47:33.038368 2019] [wsgi:error] [pid 9864:tid 139977581049600] [remote 14.143.35.158:51332] Traceback (most recent call last):
[Wed Jan 23 13:47:33.038372 2019] [wsgi:error] [pid 9864:tid 139977581049600] [remote 14.143.35.158:51332]   File "/home/ubuntu/.local/lib/python3.6/site-packages/flask/app.py", line 2292, in wsgi_app
[Wed Jan 23 13:47:33.038376 2019] [wsgi:error] [pid 9864:tid 139977581049600] [remote 14.143.35.158:51332]     response = self.full_dispatch_request()
[Wed Jan 23 13:47:33.038380 2019] [wsgi:error] [pid 9864:tid 139977581049600] [remote 14.143.35.158:51332]   File "/home/ubuntu/.local/lib/python3.6/site-packages/flask/app.py", line 1815, in full_dispatch_request
[Wed Jan 23 13:47:33.038383 2019] [wsgi:error] [pid 9864:tid 139977581049600] [remote 14.143.35.158:51332]     rv = self.handle_user_exception(e)
[Wed Jan 23 13:47:33.038387 2019] [wsgi:error] [pid 9864:tid 139977581049600] [remote 14.143.35.158:51332]   File "/home/ubuntu/.local/lib/python3.6/site-packages/flask/app.py", line 1718, in handle_user_exception
[Wed Jan 23 13:47:33.038390 2019] [wsgi:error] [pid 9864:tid 139977581049600] [remote 14.143.35.158:51332]     reraise(exc_type, exc_value, tb)
[Wed Jan 23 13:47:33.038393 2019] [wsgi:error] [pid 9864:tid 139977581049600] [remote 14.143.35.158:51332]   File "/home/ubuntu/.local/lib/python3.6/site-packages/flask/_compat.py", line 35, in reraise
[Wed Jan 23 13:47:33.038397 2019] [wsgi:error] [pid 9864:tid 139977581049600] [remote 14.143.35.158:51332]     raise value
[Wed Jan 23 13:47:33.038400 2019] [wsgi:error] [pid 9864:tid 139977581049600] [remote 14.143.35.158:51332]   File "/home/ubuntu/.local/lib/python3.6/site-packages/flask/app.py", line 1813, in full_dispatch_request
[Wed Jan 23 13:47:33.038413 2019] [wsgi:error] [pid 9864:tid 139977581049600] [remote 14.143.35.158:51332]     rv = self.dispatch_request()
[Wed Jan 23 13:47:33.038416 2019] [wsgi:error] [pid 9864:tid 139977581049600] [remote 14.143.35.158:51332]   File "/home/ubuntu/.local/lib/python3.6/site-packages/flask/app.py", line 1799, in dispatch_request
[Wed Jan 23 13:47:33.038419 2019] [wsgi:error] [pid 9864:tid 139977581049600] [remote 14.143.35.158:51332]     return self.view_functions[rule.endpoint](**req.view_args)
[Wed Jan 23 13:47:33.038422 2019] [wsgi:error] [pid 9864:tid 139977581049600] [remote 14.143.35.158:51332]   File "/home/ubuntu/flask/cc.py", line 87, in display_grid
[Wed Jan 23 13:47:33.038424 2019] [wsgi:error] [pid 9864:tid 139977581049600] [remote 14.143.35.158:51332]     df=pd.read_csv('database.csv')
[Wed Jan 23 13:47:33.038427 2019] [wsgi:error] [pid 9864:tid 139977581049600] [remote 14.143.35.158:51332]   File "/home/ubuntu/.local/lib/python3.6/site-packages/pandas/io/parsers.py", line 678, in parser_f
[Wed Jan 23 13:47:33.038430 2019] [wsgi:error] [pid 9864:tid 139977581049600] [remote 14.143.35.158:51332]     return _read(filepath_or_buffer, kwds)
[Wed Jan 23 13:47:33.038433 2019] [wsgi:error] [pid 9864:tid 139977581049600] [remote 14.143.35.158:51332]   File "/home/ubuntu/.local/lib/python3.6/site-packages/pandas/io/parsers.py", line 440, in _read
[Wed Jan 23 13:47:33.038436 2019] [wsgi:error] [pid 9864:tid 139977581049600] [remote 14.143.35.158:51332]     parser = TextFileReader(filepath_or_buffer, **kwds)
[Wed Jan 23 13:47:33.038439 2019] [wsgi:error] [pid 9864:tid 139977581049600] [remote 14.143.35.158:51332]   File "/home/ubuntu/.local/lib/python3.6/site-packages/pandas/io/parsers.py", line 787, in __init__
[Wed Jan 23 13:47:33.038442 2019] [wsgi:error] [pid 9864:tid 139977581049600] [remote 14.143.35.158:51332]     self._make_engine(self.engine)
[Wed Jan 23 13:47:33.038445 2019] [wsgi:error] [pid 9864:tid 139977581049600] [remote 14.143.35.158:51332]   File "/home/ubuntu/.local/lib/python3.6/site-packages/pandas/io/parsers.py", line 1014, in _make_engine
[Wed Jan 23 13:47:33.038448 2019] [wsgi:error] [pid 9864:tid 139977581049600] [remote 14.143.35.158:51332]     self._engine = CParserWrapper(self.f, **self.options)
[Wed Jan 23 13:47:33.038451 2019] [wsgi:error] [pid 9864:tid 139977581049600] [remote 14.143.35.158:51332]   File "/home/ubuntu/.local/lib/python3.6/site-packages/pandas/io/parsers.py", line 1708, in __init__
[Wed Jan 23 13:47:33.038454 2019] [wsgi:error] [pid 9864:tid 139977581049600] [remote 14.143.35.158:51332]     self._reader = parsers.TextReader(src, **kwds)
[Wed Jan 23 13:47:33.038457 2019] [wsgi:error] [pid 9864:tid 139977581049600] [remote 14.143.35.158:51332]   File "pandas/_libs/parsers.pyx", line 384, in pandas._libs.parsers.TextReader.__cinit__
[Wed Jan 23 13:47:33.038460 2019] [wsgi:error] [pid 9864:tid 139977581049600] [remote 14.143.35.158:51332]   File "pandas/_libs/parsers.pyx", line 695, in pandas._libs.parsers.TextReader._setup_parser_source
[Wed Jan 23 13:47:33.038464 2019] [wsgi:error] [pid 9864:tid 139977581049600] [remote 14.143.35.158:51332] FileNotFoundError: File b'database.csv' does not exist
[Wed Jan 23 13:47:33.038487 2019] [wsgi:error] [pid 9864:tid 139977581049600] [remote 14.143.35.158:51332] 
[Wed Jan 23 13:53:32.209356 2019] [wsgi:error] [pid 9995:tid 139818976438016] [remote 14.143.35.158:54770] [2019-01-23 13:53:32,207] ERROR in app: Exception on /feed [GET]
[Wed Jan 23 13:53:32.209393 2019] [wsgi:error] [pid 9995:tid 139818976438016] [remote 14.143.35.158:54770] Traceback (most recent call last):
[Wed Jan 23 13:53:32.209398 2019] [wsgi:error] [pid 9995:tid 139818976438016] [remote 14.143.35.158:54770]   File "/home/ubuntu/.local/lib/python3.6/site-packages/flask/app.py", line 2292, in wsgi_app
[Wed Jan 23 13:53:32.209401 2019] [wsgi:error] [pid 9995:tid 139818976438016] [remote 14.143.35.158:54770]     response = self.full_dispatch_request()
[Wed Jan 23 13:53:32.209414 2019] [wsgi:error] [pid 9995:tid 139818976438016] [remote 14.143.35.158:54770]   File "/home/ubuntu/.local/lib/python3.6/site-packages/flask/app.py", line 1815, in full_dispatch_request
[Wed Jan 23 13:53:32.209417 2019] [wsgi:error] [pid 9995:tid 139818976438016] [remote 14.143.35.158:54770]     rv = self.handle_user_exception(e)
[Wed Jan 23 13:53:32.209420 2019] [wsgi:error] [pid 9995:tid 139818976438016] [remote 14.143.35.158:54770]   File "/home/ubuntu/.local/lib/python3.6/site-packages/flask/app.py", line 1718, in handle_user_exception
[Wed Jan 23 13:53:32.209423 2019] [wsgi:error] [pid 9995:tid 139818976438016] [remote 14.143.35.158:54770]     reraise(exc_type, exc_value, tb)
[Wed Jan 23 13:53:32.209425 2019] [wsgi:error] [pid 9995:tid 139818976438016] [remote 14.143.35.158:54770]   File "/home/ubuntu/.local/lib/python3.6/site-packages/flask/_compat.py", line 35, in reraise
[Wed Jan 23 13:53:32.209428 2019] [wsgi:error] [pid 9995:tid 139818976438016] [remote 14.143.35.158:54770]     raise value
[Wed Jan 23 13:53:32.209431 2019] [wsgi:error] [pid 9995:tid 139818976438016] [remote 14.143.35.158:54770]   File "/home/ubuntu/.local/lib/python3.6/site-packages/flask/app.py", line 1813, in full_dispatch_request
[Wed Jan 23 13:53:32.209434 2019] [wsgi:error] [pid 9995:tid 139818976438016] [remote 14.143.35.158:54770]     rv = self.dispatch_request()
[Wed Jan 23 13:53:32.209437 2019] [wsgi:error] [pid 9995:tid 139818976438016] [remote 14.143.35.158:54770]   File "/home/ubuntu/.local/lib/python3.6/site-packages/flask/app.py", line 1799, in dispatch_request
[Wed Jan 23 13:53:32.209439 2019] [wsgi:error] [pid 9995:tid 139818976438016] [remote 14.143.35.158:54770]     return self.view_functions[rule.endpoint](**req.view_args)
[Wed Jan 23 13:53:32.209442 2019] [wsgi:error] [pid 9995:tid 139818976438016] [remote 14.143.35.158:54770]   File "/home/ubuntu/flask/cc.py", line 87, in display_grid
[Wed Jan 23 13:53:32.209445 2019] [wsgi:error] [pid 9995:tid 139818976438016] [remote 14.143.35.158:54770]     df=pd.read_csv('database.csv')
[Wed Jan 23 13:53:32.209448 2019] [wsgi:error] [pid 9995:tid 139818976438016] [remote 14.143.35.158:54770]   File "/home/ubuntu/.local/lib/python3.6/site-packages/pandas/io/parsers.py", line 678, in parser_f
[Wed Jan 23 13:53:32.209451 2019] [wsgi:error] [pid 9995:tid 139818976438016] [remote 14.143.35.158:54770]     return _read(filepath_or_buffer, kwds)
[Wed Jan 23 13:53:32.209453 2019] [wsgi:error] [pid 9995:tid 139818976438016] [remote 14.143.35.158:54770]   File "/home/ubuntu/.local/lib/python3.6/site-packages/pandas/io/parsers.py", line 440, in _read
[Wed Jan 23 13:53:32.209456 2019] [wsgi:error] [pid 9995:tid 139818976438016] [remote 14.143.35.158:54770]     parser = TextFileReader(filepath_or_buffer, **kwds)
[Wed Jan 23 13:53:32.209459 2019] [wsgi:error] [pid 9995:tid 139818976438016] [remote 14.143.35.158:54770]   File "/home/ubuntu/.local/lib/python3.6/site-packages/pandas/io/parsers.py", line 787, in __init__
[Wed Jan 23 13:53:32.209462 2019] [wsgi:error] [pid 9995:tid 139818976438016] [remote 14.143.35.158:54770]     self._make_engine(self.engine)
[Wed Jan 23 13:53:32.209465 2019] [wsgi:error] [pid 9995:tid 139818976438016] [remote 14.143.35.158:54770]   File "/home/ubuntu/.local/lib/python3.6/site-packages/pandas/io/parsers.py", line 1014, in _make_engine
[Wed Jan 23 13:53:32.209468 2019] [wsgi:error] [pid 9995:tid 139818976438016] [remote 14.143.35.158:54770]     self._engine = CParserWrapper(self.f, **self.options)
[Wed Jan 23 13:53:32.209470 2019] [wsgi:error] [pid 9995:tid 139818976438016] [remote 14.143.35.158:54770]   File "/home/ubuntu/.local/lib/python3.6/site-packages/pandas/io/parsers.py", line 1708, in __init__
[Wed Jan 23 13:53:32.209473 2019] [wsgi:error] [pid 9995:tid 139818976438016] [remote 14.143.35.158:54770]     self._reader = parsers.TextReader(src, **kwds)
[Wed Jan 23 13:53:32.209476 2019] [wsgi:error] [pid 9995:tid 139818976438016] [remote 14.143.35.158:54770]   File "pandas/_libs/parsers.pyx", line 384, in pandas._libs.parsers.TextReader.__cinit__
[Wed Jan 23 13:53:32.209482 2019] [wsgi:error] [pid 9995:tid 139818976438016] [remote 14.143.35.158:54770]   File "pandas/_libs/parsers.pyx", line 695, in pandas._libs.parsers.TextReader._setup_parser_source
[Wed Jan 23 13:53:32.209486 2019] [wsgi:error] [pid 9995:tid 139818976438016] [remote 14.143.35.158:54770] FileNotFoundError: File b'database.csv' does not exist
[Wed Jan 23 13:53:32.209508 2019] [wsgi:error] [pid 9995:tid 139818976438016] [remote 14.143.35.158:54770] 
